3.8 develop-inst-noop: /home/almazhan/Desktop/posix-omni-parser-copy
3.8 installed: appdirs==1.4.3,attrs==20.3.0,CacheControl==0.12.6,certifi==2019.11.28,chardet==3.0.4,colorama==0.4.3,contextlib2==0.6.0,coverage==5.5,distlib==0.3.0,distro==1.4.0,html5lib==1.0.1,idna==2.8,iniconfig==1.1.1,ipaddr==2.2.0,lockfile==0.12.2,msgpack==0.6.2,packaging==20.3,pep517==0.8.2,pluggy==0.13.1,-e git+https://github.com/almazhankapan/posix-omni-parser.git@526fd2761c687d2d3dc0f03ce21d5a2eaa4bd4c7#egg=posix_omni_parser,progress==1.5,py==1.10.0,pyparsing==2.4.6,pytest==6.2.2,pytoml==0.1.21,requests==2.22.0,retrying==1.3.3,six==1.14.0,toml==0.10.2,urllib3==1.25.8,webencodings==0.5.1
3.8 run-test-pre: PYTHONHASHSEED='2812322221'
3.8 run-test: commands[0] | bash -c 'if [ ! -f '"'"'test/syscall_definitions.pickle'"'"' ]; then cd test/; parse_syscall_definitions; cd ..; fi'
WARNING: test command found but not installed in testenv
  cmd: /usr/bin/bash
  env: /home/almazhan/Desktop/posix-omni-parser-copy/.tox/3.8
Maybe you forgot to specify a dependency? See also the whitelist_externals envconfig setting.

DEPRECATION WARNING: this will be an error in tox 4 and above!
3.8 run-test: commands[1] | coverage erase
3.8 run-test: commands[2] | coverage run --source=posix_omni_parser,sysDef -m pytest
============================= test session starts ==============================
platform linux -- Python 3.8.5, pytest-6.2.2, py-1.10.0, pluggy-0.13.1
cachedir: .tox/3.8/.pytest_cache
rootdir: /home/almazhan/Desktop/posix-omni-parser-copy
collected 2 items / 1 error / 1 selected

==================================== ERRORS ====================================
____________________ ERROR collecting test/test_syscalls.py ____________________
.tox/3.8/lib/python3.8/site-packages/_pytest/python.py:578: in _importtestmodule
    mod = import_path(self.fspath, mode=importmode)
.tox/3.8/lib/python3.8/site-packages/_pytest/pathlib.py:531: in import_path
    importlib.import_module(module_name)
/usr/lib/python3.8/importlib/__init__.py:127: in import_module
    return _bootstrap._gcd_import(name[level:], package, level)
<frozen importlib._bootstrap>:1014: in _gcd_import
    ???
<frozen importlib._bootstrap>:991: in _find_and_load
    ???
<frozen importlib._bootstrap>:975: in _find_and_load_unlocked
    ???
<frozen importlib._bootstrap>:671: in _load_unlocked
    ???
.tox/3.8/lib/python3.8/site-packages/_pytest/assertion/rewrite.py:170: in exec_module
    exec(co, module.__dict__)
test/test_syscalls.py:2: in <module>
    from posix_omni_parser import Trace
E     File "/home/almazhan/Desktop/posix-omni-parser-copy/posix_omni_parser/Trace.py", line 100
E       raise IOError("Could not find trace file `" + self.trace_path + "`")
E                                                                          ^
E   TabError: inconsistent use of tabs and spaces in indentation
=========================== short test summary info ============================
ERROR test/test_syscalls.py
!!!!!!!!!!!!!!!!!!!! Interrupted: 1 error during collection !!!!!!!!!!!!!!!!!!!!
=============================== 1 error in 0.24s ===============================
ERROR: InvocationError for command /home/almazhan/Desktop/posix-omni-parser-copy/.tox/3.8/bin/coverage run --source=posix_omni_parser,sysDef -m pytest (exited with code 2)
___________________________________ summary ____________________________________
ERROR:   3.8: commands failed
